<?xml version="1.0"?>
<robot name="my_robot">
  <!-- Base footprint -->
  <link name="base_footprint">
    <visual>
      <geometry>
        <sphere radius="0.001"/>
      </geometry>
    </visual>
    <collision>
      <geometry>
        <sphere radius="0.001"/>
      </geometry>
    </collision>
  </link>

  <!-- Base link: Cylinder (diameter 0.5 m, height 0.3 m) -->
  <link name="base_link">
    <visual>
      <geometry>
        <cylinder radius="0.25" length="0.3"/>
      </geometry>
      <material name="blue">
        <color rgba="0 0 1 1"/>
      </material>
    </visual>
    <collision>
      <geometry>
        <cylinder radius="0.25" length="0.3"/>
      </geometry>
    </collision>
    <inertial>
      <mass value="15.0"/>
      <origin xyz="0 0 0" rpy="0 0 0"/>
      <!-- For a solid cylinder: Ixx = Iyy = 1/12*m*(3r^2+h^2), Izz=1/2*m*r^2 -->
      <inertia ixx="0.346875" ixy="0.0" ixz="0.0" iyy="0.346875" iyz="0.0" izz="0.46875"/>
    </inertial>
  </link>

  <!-- Gazebo color for base_link -->
  <gazebo reference="base_link">
    <material>Gazebo/Black</material>
  </gazebo>

  <!-- Left wheel (radius = 0.025 m) -->
  <link name="left_wheel">
    <visual>
      <origin rpy="1.5708 0 0"/>
      <geometry>
        <cylinder radius="0.025" length="0.02"/>
      </geometry>
      <material name="red">
        <color rgba="1 0 0 1"/>
      </material>
    </visual>
    <collision>
      <origin rpy="1.5708 0 0"/>
      <geometry>
        <cylinder radius="0.025" length="0.02"/>
      </geometry>
      <surface>
        <friction>
          <ode>
            <mu>1.0</mu>
            <mu2>1.0</mu2>
            <slip1>0.0</slip1>
            <slip2>0.0</slip2>
          </ode>
        </friction>
      </surface>
    </collision>
    <inertial>
      <mass value="3.0"/>
      <origin xyz="0 0 0" rpy="0 0 0"/>
      <inertia ixx="0.00056875" ixy="0" ixz="0" iyy="0.0009375" iyz="0" izz="0.00056875"/>
    </inertial>
  </link>

  <!-- Gazebo color for left wheel -->
  <gazebo reference="left_wheel">
    <material>Gazebo/Red</material>
    <mu1>0.8</mu1>
    <mu2>0.8</mu2>
    <kp>500000.0</kp>
    <kd>10.0</kd>
    <minDepth>0.001</minDepth>
    <maxVel>0.1</maxVel>
  </gazebo>

  <!-- Right wheel (radius = 0.025 m) -->
  <link name="right_wheel">
    <visual>
      <origin rpy="1.5708 0 0"/>
      <geometry>
        <cylinder radius="0.025" length="0.02"/>
      </geometry>
      <material name="red">
        <color rgba="1 0 0 1"/>
      </material>
    </visual>
    <collision>
      <origin rpy="1.5708 0 0"/>
      <geometry>
        <cylinder radius="0.025" length="0.02"/>
      </geometry>
      <surface>
        <friction>
          <ode>
            <mu>1.0</mu>
            <mu2>1.0</mu2>
            <slip1>0.0</slip1>
            <slip2>0.0</slip2>
          </ode>
        </friction>
      </surface>
    </collision>
    <inertial>
      <mass value="3.0"/>
      <origin xyz="0 0 0" rpy="0 0 0"/>
      <inertia ixx="0.00056875" ixy="0" ixz="0" iyy="0.0009375" iyz="0" izz="0.00056875"/>
    </inertial>
  </link>

  <!-- Gazebo color for right wheel -->
  <gazebo reference="right_wheel">
    <material>Gazebo/Red</material>
    <mu1>0.8</mu1>
    <mu2>0.8</mu2>
    <kp>500000.0</kp>
    <kd>10.0</kd>
    <minDepth>0.001</minDepth>
    <maxVel>0.1</maxVel>
  </gazebo>

  <!-- Front caster wheel (radius = 0.025 m) -->
  <link name="front_caster">
    <visual>
      <geometry>
        <sphere radius="0.025"/>
      </geometry>
      <material name="grey">
        <color rgba="0.5 0.5 0.5 1"/>
      </material>
    </visual>
    <collision>
      <geometry>
        <sphere radius="0.025"/>
      </geometry>
      <!-- Set friction to 0.0 as required -->
      <surface>
        <friction>
          <ode>
            <mu>0.0</mu>
            <mu2>0.0</mu2>
          </ode>
        </friction>
      </surface>
    </collision>
    <inertial>
      <!-- Revised inertial: For a solid sphere with mass=2.0 and radius=0.025, I = (2/5)*m*r^2 -->
      <mass value="2.0"/>
      <origin xyz="0 0 0" rpy="0 0 0"/>
      <inertia ixx="0.0005" ixy="0" ixz="0" iyy="0.0005" iyz="0" izz="0.0005"/>
    </inertial>
  </link>

  <!-- Gazebo color for front caster -->
  <gazebo reference="front_caster">
    <material>Gazebo/Grey</material>
    <mu1>0.0</mu1>
    <mu2>0.0</mu2>
  </gazebo>

  <!-- Back caster wheel (radius = 0.025 m) -->
  <link name="back_caster">
    <visual>
      <geometry>
        <sphere radius="0.025"/>
      </geometry>
      <material name="grey">
        <color rgba="0.5 0.5 0.5 1"/>
      </material>
    </visual>
    <collision>
      <geometry>
        <sphere radius="0.025"/>
      </geometry>
      <surface>
        <friction>
          <ode>
            <mu>0.0</mu>
            <mu2>0.0</mu2>
          </ode>
        </friction>
      </surface>
    </collision>
    <inertial>
      <!-- Revised inertial same as front caster -->
      <mass value="2.0"/>
      <origin xyz="0 0 0" rpy="0 0 0"/>
      <inertia ixx="0.0005" ixy="0" ixz="0" iyy="0.0005" iyz="0" izz="0.0005"/>
    </inertial>
  </link>

  <!-- Gazebo color for back caster -->
  <gazebo reference="back_caster">
    <material>Gazebo/Grey</material>
    <mu1>0.0</mu1>
    <mu2>0.0</mu2>
  </gazebo>

  <!-- Front laser scanner -->
  <link name="front_laser">
    <visual>
      <geometry>
        <cylinder radius="0.04" length="0.05"/>
      </geometry>
      <material name="black">
        <color rgba="0 0 0 1"/>
      </material>
    </visual>
    <collision>
      <geometry>
        <cylinder radius="0.04" length="0.05"/>
      </geometry>
    </collision>
    <inertial>
      <mass value="1.0"/>
      <origin xyz="0 0 0" rpy="0 0 0"/>
      <!-- Revised using standard formula: Ixx=Iyy = (1/12)*(3r^2+l^2), Izz = 1/2*r^2 -->
      <inertia ixx="0.00060833" ixy="0" ixz="0" iyy="0.00060833" iyz="0" izz="0.0008"/>
    </inertial>
  </link>

  <!-- Gazebo color for front laser -->
  <gazebo reference="front_laser">
    <material>Gazebo/Purple</material>
  </gazebo>

  <!-- Joints -->
  <!-- Base footprint to base_link joint -->
  <joint name="base_footprint_joint" type="fixed">
    <parent link="base_footprint"/>
    <child link="base_link"/>
    <origin xyz="0 0 0.15" rpy="0 0 0"/>
  </joint>

  <!-- Left wheel joint -->
  <joint name="left_wheel_joint" type="continuous">
    <parent link="base_link"/>
    <child link="left_wheel"/>
    <origin xyz="0 0.2 -0.15" rpy="0 0 0"/>
    <axis xyz="0 1 0"/>
    <!-- Adjust dynamics as necessary -->
    <dynamics damping="0.1" friction="0.1"/>
  </joint>

  <!-- Right wheel joint -->
  <joint name="right_wheel_joint" type="continuous">
    <parent link="base_link"/>
    <child link="right_wheel"/>
    <origin xyz="0 -0.2 -0.15" rpy="0 0 0"/>
    <axis xyz="0 1 0"/>
    <dynamics damping="0.1" friction="0.1"/>
  </joint>

  <!-- Front caster wheel joint -->
  <joint name="front_caster_joint" type="fixed">
    <parent link="base_link"/>
    <child link="front_caster"/>
    <origin xyz="0.1 0.0 -0.125" rpy="0 0 0"/>
  </joint>

  <!-- Back caster wheel joint -->
  <joint name="back_caster_joint" type="fixed">
    <parent link="base_link"/>
    <child link="back_caster"/>
    <origin xyz="-0.1 0.0 -0.125" rpy="0 0 0"/>
  </joint>

  <!-- Front laser joint -->
  <joint name="front_laser_joint" type="fixed">
    <parent link="base_link"/>
    <child link="front_laser"/>
    <origin xyz="0.25 0.0 0.075" rpy="3.14159 0 0"/>
  </joint>

  <!-- Gazebo plugins -->
  <gazebo>
    <plugin name="differential_drive_controller" filename="libgazebo_ros_diff_drive.so">
      <robotNamespace>/</robotNamespace>
      <leftJoint>left_wheel_joint</leftJoint>
      <rightJoint>right_wheel_joint</rightJoint>
      <wheelSeparation>0.4</wheelSeparation>
      <wheelDiameter>0.05</wheelDiameter>
      <commandTopic>cmd_vel</commandTopic>
      <odometryTopic>odom</odometryTopic>
      <odometryFrame>odom</odometryFrame>
      <robotBaseFrame>base_footprint</robotBaseFrame>
      <publishWheelTF>false</publishWheelTF>
      <publishOdomTF>true</publishOdomTF>
      <publishWheelJointState>true</publishWheelJointState>
      <legacyMode>false</legacyMode>
      <updateRate>30</updateRate>
      <odometrySource>world</odometrySource>
      <publishTf>true</publishTf>
      <torque>20</torque>
      <maxVelocity>0.5</maxVelocity>
      <rightWheelTorqueMult>1.05</rightWheelTorqueMult>
    </plugin>
  </gazebo>
  
  <!-- Laser scanner plugin -->
  <gazebo reference="front_laser">
    <sensor type="ray" name="front_laser_sensor">
      <pose>0 0 0 0 0 0</pose>
      <visualize>false</visualize>
      <update_rate>10</update_rate>
      <ray>
        <scan>
          <horizontal>
            <samples>360</samples>
            <resolution>1</resolution>
            <min_angle>-3.14159</min_angle>
            <max_angle>3.14159</max_angle>
          </horizontal>
        </scan>
        <range>
          <min>0.1</min>
          <max>10.0</max>
          <resolution>0.01</resolution>
        </range>
        <noise>
          <type>gaussian</type>
          <mean>0.0</mean>
          <stddev>0.01</stddev>
        </noise>
      </ray>
      <plugin name="gazebo_ros_head_hokuyo_controller" filename="libgazebo_ros_laser.so">
        <topicName>scan</topicName>
        <frameName>front_laser</frameName>
      </plugin>
    </sensor>
  </gazebo>

</robot>
